Workbook

Sheet Main
N3: Price | O3: {=_xlfn.LET(_xlpm.p,_xlfn.STOCKHISTORY("TSLA",TODAY()-14,TODAY(),0,0,1),INDEX(_xlpm.p,ROWS(_xlpm.p),1))} -> 328.58
N4: Shares | O4: 3949.5474
N5: MC | O5: =O3*O4 -> 1297742.3
N6: Cash | O6: =15219+28305 -> 43524
N7: Debt | O7: =1418+7924 -> 9342
N8: EV (Enterprise Value) | O8: =O5-O6+O7 -> 1263560.3

Sheet Model
A1: Main
C3: Q122 | D3: Q222 | E3: Q322 | F3: Q422 | G3: Q123 | H3: Q223 | I3: Q323 | J3: Q423 | K3: Q124 | L3: Q224 | M3: Q324 | N3: Q424 | O3: Q125 | P3: Q225 | Q3: Q325 | R3: Q425 | S3: Q126 | T3: Q226 | U3: Q326 | V3: Q426 | W3: Q127 | X3: Q227 | Y3: Q327 | Z3: Q427 | AB3: 2022 | AC3: 2023 | AD3: 2024 | AE3: 2025 | AF3: 2026 | AG3: 2027 | AH3: 2028 | AI3: 2029 | AJ3: 2030 | AK3: 2031 | AM3: Valuation Block
B4: Car Deliveries | C4: 310048 | D4: 254695 | E4: 343830 | F4: 405278 | G4: 422875 | H4: 466140 | I4: 435059 | J4: 484507 | K4: 386810 | L4: 443956 | M4: 462890 | N4: 495570 | O4: 336681 | P4: 384122 | Q4: 497099 | R4: 418227 | S4: 358023 | T4: 480126 | U4: 497099 | V4: 418227 | W4: 358023 | X4: 480126 | Y4: 497099 | Z4: 418227
B5: Energy Storage GWH | C5: 0.846 | D5: 1.133 | E5: 2.1 | F5: 2.462 | G5: 3.889 | H5: 3.653 | I5: 3.98 | J5: 3.202 | K5: 4.053 | L5: 9.4 | M5: 6.9 | N5: 11 | O5: 10.4 | P5: 9.6 | Q5: 12.5 | R5: 14.2 | S5: 8.8 | T5: 13.5 | U5: =1.15*Q5 -> 14.375 | V5: =1.15*R5 -> 16.33 | W5: =1.15*S5 -> 10.12 | X5: =1.15*T5 -> 15.525 | Y5: =1.15*U5 -> 16.53125 | Z5: =1.15*V5 -> 18.7795
B8: Automotive sales | C8: 15514 | D8: 13670 | E8: 17785 | F8: 20241 | G8: 18878 | H8: 20419 | I8: 18582 | J8: 20630 | K8: 16460 | L8: 18530 | M8: 18831 | N8: 18659 | O8: 12925 | P8: 15787 | Q8: 20359 | R8: 16750 | S8: 15473 | T8: 20006 | U8: =U4*U44/1000000 -> 20359 | V8: =V4*V44/1000000 -> 16750 | W8: =W4*W44/1000000 -> 15473 | X8: =X4*X44/1000000 -> 20006 | Y8: =Y4*Y44/1000000 -> 20359 | Z8: =Z4*Z44/1000000 -> 16750 | AB8: =SUM(C8:F8) -> 67210 | AC8: =SUM(G8:J8) -> 78509 | AD8: =SUM(K8:N8) -> 72480 | AE8: =SUM(O8:R8) -> 65821 | AF8: =SUM(S8:V8) -> 72588 | AG8: =SUM(W8:Z8) -> 72588 | AH8: =AG8*1.05 -> 76217.4 | AI8: =AH8*1.05 -> 80028.27 | AJ8: =AI8*1.05 -> 84029.684 | AK8: =AJ8*1.05 -> 88231.168
B9: Automotive leasing revenue | C9: 668 | D9: 588 | E9: 621 | F9: 599 | G9: 564 | H9: 567 | I9: 489 | J9: 500 | K9: 476 | L9: 458 | M9: 446 | N9: 447 | O9: 447 | P9: 439 | Q9: 429 | R9: 397 | S9: 381 | T9: 364 | U9: =Q9 -> 429 | V9: =R9 -> 397 | W9: =S9 -> 381 | X9: =T9 -> 364 | Y9: =U9 -> 429 | Z9: =V9 -> 397 | AB9: =SUM(C9:F9) -> 2476 | AC9: =SUM(G9:J9) -> 2120 | AD9: =SUM(K9:N9) -> 1827 | AE9: =SUM(O9:R9) -> 1712 | AF9: =SUM(S9:V9) -> 1571 | AG9: =SUM(W9:Z9) -> 1571 | AH9: =AG9*1.05 -> 1649.55 | AI9: =AH9*1.05 -> 1732.0275 | AJ9: =AI9*1.05 -> 1818.6289 | AK9: =AJ9*1.05 -> 1909.5603
B10: Automotive regulatory credits | C10: 679 | D10: 344 | E10: 286 | F10: 467 | G10: 521 | H10: 282 | I10: 554 | J10: 433 | K10: 442 | L10: 890 | M10: 739 | N10: 692 | O10: 595 | P10: 435 | Q10: 417 | R10: 546 | S10: 380 | T10: 146 | U10: =AVERAGE(Q10:T10) -> 372.25 | V10: =U10 -> 372.25 | W10: =V10 -> 372.25 | X10: =W10 -> 372.25 | Y10: =X10 -> 372.25 | Z10: =Y10 -> 372.25 | AB10: =SUM(C10:F10) -> 1776 | AC10: =SUM(G10:J10) -> 1790 | AD10: =SUM(K10:N10) -> 2763 | AE10: =SUM(O10:R10) -> 1993 | AF10: =SUM(S10:V10) -> 1270.5 | AG10: =SUM(W10:Z10) -> 1489 | AH10: =AG10 -> 1489 | AI10: =AH10 -> 1489 | AJ10: =AI10 -> 1489 | AK10: =AJ10 -> 1489
B11: Energy generation and storage sales | C11: 616 | D11: 866 | E11: 1117 | F11: 1310 | G11: 1529 | H11: 1509 | I11: 1559 | J11: 1438 | K11: 1635 | L11: 3014 | M11: 2376 | N11: 3061 | O11: 2730 | P11: 2789 | Q11: 3415 | R11: 3837 | S11: 2408 | T11: 3139 | U11: =U5*U45/1000000 -> 3927.25 | V11: =V5*V45/1000000 -> 4412.55 | W11: =W5*W45/1000000 -> 2769.2 | X11: =X5*X45/1000000 -> 3609.85 | Y11: =Y5*Y45/1000000 -> 4516.3375 | Z11: =Z5*Z45/1000000 -> 5074.4325 | AB11: =SUM(C11:F11) -> 3909 | AC11: =SUM(G11:J11) -> 6035 | AD11: =SUM(K11:N11) -> 10086 | AE11: =SUM(O11:R11) -> 12771 | AF11: =SUM(S11:V11) -> 13886.8 | AG11: =SUM(W11:Z11) -> 15969.82 | AH11: =AG11*1.1 -> 17566.802 | AI11: =AH11*1.1 -> 19323.482 | AJ11: =AI11*1.1 -> 21255.83 | AK11: =AJ11*1.1 -> 23381.413
B12: Services Sales | C12: 1279 | D12: 1466 | E12: 1645 | F12: 1701 | G12: 1837 | H12: 2150 | I12: 2166 | J12: 2166 | K12: 2288 | L12: 2608 | M12: 2790 | N12: 2848 | O12: 2638 | P12: 3046 | Q12: 3475 | R12: 3371 | S12: 3745 | T12: 4581 | U12: =Q12*1.15 -> 3996.25 | V12: =R12*1.15 -> 3876.65 | W12: =S12*1.15 -> 4306.75 | X12: =T12*1.15 -> 5268.15 | Y12: =U12*1.15 -> 4595.6875 | Z12: =V12*1.15 -> 4458.1475 | AB12: =SUM(C12:F12) -> 6091 | AC12: =SUM(G12:J12) -> 8319 | AD12: =SUM(K12:N12) -> 10534 | AE12: =SUM(O12:R12) -> 12530 | AF12: =SUM(S12:V12) -> 16198.9 | AG12: =SUM(W12:Z12) -> 18628.735 | AH12: =AG12*1.15 -> 21423.045 | AI12: =AH12*1.15 -> 24636.502 | AJ12: =AI12*1.15 -> 28331.977 | AK12: =AJ12*1.15 -> 32581.774
B13: Total Revenue | C13: =C12+C11+C8+C10+C9 -> 18756 | D13: =D12+D11+D8+D10+D9 -> 16934 | E13: =E12+E11+E8+E10+E9 -> 21454 | F13: =F12+F11+F8+F10+F9 -> 24318 | G13: =G12+G11+G8+G10+G9 -> 23329 | H13: =H12+H11+H8+H10+H9 -> 24927 | I13: =I12+I11+I8+I10+I9 -> 23350 | J13: =J12+J11+J8+J10+J9 -> 25167 | ... T13: =T12+T11+T8+T10+T9 -> 28236 | U13: =SUM(U8:U12) -> 29083.75 | V13: =SUM(V8:V12) -> 25808.45 | W13: =SUM(W8:W12) -> 23302.2 | X13: =SUM(X8:X12) -> 29620.25 | Y13: =SUM(Y8:Y12) -> 30272.275 | Z13: =SUM(Z8:Z12) -> 27051.83 | AB13: =SUM(C13:F13) -> 81462 | AC13: =SUM(G13:J13) -> 96773 | AD13: =SUM(K13:N13) -> 97690 | AE13: =SUM(O13:R13) -> 94827 | AF13: =SUM(S13:V13) -> 105515.2 | AG13: =SUM(W13:Z13) -> 110246.56 | AH13: =SUM(X13:AA13) -> 86944.355 | AI13: =SUM(Y13:AB13) -> 138786.11 | AJ13: =SUM(Z13:AC13) -> 205286.83 | AK13: =SUM(AA13:AD13) -> 275925
B14: Automotive COGS | C14: 10914 | D14: 10153 | E14: 13099 | F14: 15433 | G14: 15422 | H14: 16841 | I14: 15656 | J14: 17202 | K14: 13897 | L14: 15962 | M14: 15743 | N14: 16268 | O14: 11461 | P14: 13567 | Q14: 17365 | R14: 13874 | S14: 12616 | T14: 16866 | U14: =U8*(1-U47) -> 16997.938 | V14: =V8*(1-V47) -> 13984.747 | W14: =W8*(1-W47) -> 12918.567 | X14: =X8*(1-X47) -> 16703.215 | Y14: =Y8*(1-Y47) -> 16997.938 | Z14: =Z8*(1-Z47) -> 13984.747 | AB14: =SUM(C14:F14) -> 49599 | AC14: =SUM(G14:J14) -> 65121 | AD14: =SUM(K14:N14) -> 61870 | AE14: =SUM(O14:R14) -> 56267 | AF14: =SUM(S14:V14) -> 60464.685 | AG14: =SUM(W14:Z14) -> 60604.467 | AH14: =SUM(X14:AA14) -> 47685.9 | AI14: =SUM(Y14:AB14) -> 80581.685 | AJ14: =SUM(Z14:AC14) -> 128704.75 | AK14: =SUM(AA14:AD14) -> 176590
B15: Automotive Leasing COGS | C15: 408 | D15: 368 | E15: 381 | F15: 352 | G15: 333 | H15: 338 | I15: 301 | J15: 296 | K15: 269 | L15: 245 | M15: 247 | N15: 242 | O15: 239 | P15: 228 | Q15: 225 | R15: 206 | S15: 196 | T15: 187 | U15: =U9*(1-U48) -> 222.17258 | V15: =V9*(1-V48) -> 205.60026 | W15: =W9*(1-W48) -> 197.31411 | X15: =X9*(1-X48) -> 188.51006 | Y15: =Y9*(1-Y48) -> 222.17258 | Z15: =Z9*(1-Z48) -> 205.60026 | AB15: =SUM(C15:F15) -> 1509 | AC15: =SUM(G15:J15) -> 1268 | AD15: =SUM(K15:N15) -> 1003 | AE15: =SUM(O15:R15) -> 898 | AF15: =SUM(S15:V15) -> 810.77284 | AG15: =SUM(W15:Z15) -> 813.59701 | AH15: =SUM(X15:AA15) -> 616.2829 | AI15: =SUM(Y15:AB15) -> 1936.7728 | AJ15: =SUM(Z15:AC15) -> 2982.6003 | AK15: =SUM(AA15:AD15) -> 3780
B16: Energy generation and storage COGS | C16: 688 | D16: 769 | E16: 1013 | F16: 1151 | G16: 1361 | H16: 1231 | I16: 1178 | J16: 1124 | K16: 1232 | L16: 2274 | M16: 1651 | N16: 2289 | O16: 1945 | P16: 1943 | Q16: 2342 | R16: 2739 | S16: 1456 | T16: 2499 | U16: =U11*(1-U49) -> 2749.4692 | V16: =V11*(1-V49) -> 3089.2279 | W16: =W11*(1-W49) -> 1938.7179 | X16: =X11*(1-X49) -> 2527.2573 | Y16: =Y11*(1-Y49) -> 3161.8895 | Z16: =Z11*(1-Z49) -> 3552.612 | AB16: =SUM(C16:F16) -> 3621 | AC16: =SUM(G16:J16) -> 4894 | AD16: =SUM(K16:N16) -> 7446 | AE16: =SUM(O16:R16) -> 8969 | AF16: =SUM(S16:V16) -> 9793.697 | AG16: =SUM(W16:Z16) -> 11180.477 | AH16: =SUM(X16:AA16) -> 9241.7589 | AI16: =SUM(Y16:AB16) -> 10335.502 | AJ16: =SUM(Z16:AC16) -> 12067.612 | AK16: =SUM(AA16:AD16) -> 15961
B17: Services COGS | C17: 1286 | D17: 1410 | E17: 1579 | F17: 1605 | G17: 1702 | H17: 1984 | I17: 2037 | J17: 2107 | K17: 2207 | L17: 2441 | M17: 2544 | N17: 2729 | O17: 2537 | P17: 2880 | Q17: 3109 | R17: 3073 | S17: 3399 | T17: 3933 | U17: =U12*(1-U50) -> 3355.4985 | V17: =V12*(1-V50) -> 3408.9487 | W17: =W12*(1-W50) -> 3752.4416 | X17: =X12*(1-X50) -> 4542.2718 | Y17: =Y12*(1-Y50) -> 3966.6792 | Z17: =Z12*(1-Z50) -> 3874.1212 | AB17: =SUM(C17:F17) -> 5880 | AC17: =SUM(G17:J17) -> 7830 | AD17: =SUM(K17:N17) -> 9921 | AE17: =SUM(O17:R17) -> 11599 | AF17: =SUM(S17:V17) -> 14096.447 | AG17: =SUM(W17:Z17) -> 16135.514 | AH17: =SUM(X17:AA17) -> 12383.072 | AI17: =SUM(Y17:AB17) -> 13720.8 | AJ17: =SUM(Z17:AC17) -> 17584.121 | AK17: =SUM(AA17:AD17) -> 23631
B18: Total COGS | C18: =C17+C16+C14+C15 -> 13296 | D18: =D17+D16+D14+D15 -> 12700 | E18: =E17+E16+E14+E15 -> 16072 | F18: =F17+F16+F14+F15 -> 18541 | G18: =G17+G16+G14+G15 -> 18818 | H18: =H17+H16+H14+H15 -> 20394 | I18: =I17+I16+I14+I15 -> 19172 | J18: =J17+J16+J14+J15 -> 20729 | ... T18: =T17+T16+T14+T15 -> 23485 | U18: =SUM(U14:U17) -> 23325.079 | V18: =SUM(V14:V17) -> 20688.524 | W18: =SUM(W14:W17) -> 18807.04 | X18: =SUM(X14:X17) -> 23961.254 | Y18: =SUM(Y14:Y17) -> 24348.68 | Z18: =SUM(Z14:Z17) -> 21617.081 | AB18: =SUM(C18:F18) -> 60609 | AC18: =SUM(G18:J18) -> 79113 | AD18: =SUM(K18:N18) -> 80240 | AE18: =SUM(O18:R18) -> 77733 | AF18: =SUM(S18:V18) -> 85165.603 | AG18: =SUM(W18:Z18) -> 88734.055 | AH18: =SUM(X18:AA18) -> 69927.014 | AI18: =SUM(Y18:AB18) -> 106574.76 | AJ18: =SUM(Z18:AC18) -> 161339.08 | AK18: =SUM(AA18:AD18) -> 219962
B19: Gross Profit | C19: =C13-C18 -> 5460 | D19: =D13-D18 -> 4234 | E19: =E13-E18 -> 5382 | F19: =F13-F18 -> 5777 | G19: =G13-G18 -> 4511 | H19: =H13-H18 -> 4533 | I19: =I13-I18 -> 4178 | J19: =J13-J18 -> 4438 | ... Z19: =Z13-Z18 -> 5434.7493 | AB19: =SUM(C19:F19) -> 20853 | AC19: =SUM(G19:J19) -> 17660 | AD19: =SUM(K19:N19) -> 17450 | AE19: =SUM(O19:R19) -> 17094 | AF19: =SUM(S19:V19) -> 20349.597 | AG19: =SUM(W19:Z19) -> 21512.5 | AH19: =SUM(X19:AA19) -> 17017.341 | AI19: =SUM(Y19:AB19) -> 32211.345 | AJ19: =SUM(Z19:AC19) -> 43947.749 | AK19: =SUM(AA19:AD19) -> 55963
B20: R&D | C20: 865 | D20: 667 | E20: 733 | F20: 810 | G20: 771 | H20: 943 | I20: 1161 | J20: 1094 | K20: 1151 | L20: 1074 | M20: 1039 | N20: 1276 | O20: 1409 | P20: 1589 | Q20: 1630 | R20: 1783 | S20: 1946 | T20: 2371 | U20: =U51*U13 -> 2185.0422 | V20: =V51*V13 -> 1938.9711 | W20: =W51*W13 -> 1750.6783 | X20: =X51*X13 -> 2225.3491 | Y20: =Y51*Y13 -> 2274.3353 | Z20: =Z51*Z13 -> 2032.3854 | AB20: =SUM(C20:F20) -> 3075 | AC20: =SUM(G20:J20) -> 3969 | AD20: =SUM(K20:N20) -> 4540 | AE20: =SUM(O20:R20) -> 6411 | AF20: =SUM(S20:V20) -> 8441.0133 | AG20: =SUM(W20:Z20) -> 8282.7481 | AH20: =SUM(X20:AA20) -> 6532.0697 | AI20: =SUM(Y20:AB20) -> 7381.7207 | AJ20: =SUM(Z20:AC20) -> 9076.3854 | AK20: =SUM(AA20:AD20) -> 11584
B21: Selling General and Administrative (SG&A) | C21: 992 | D21: 961 | E21: 961 | F21: 1032 | G21: 1076 | H21: 1191 | I21: 1253 | J21: 1280 | K21: 1374 | L21: 1277 | M21: 1186 | N21: 1313 | O21: 1251 | P21: 1366 | Q21: 1562 | R21: 1655 | S21: 1833 | T21: 1982 | U21: =U52*U13 -> 1993.1983 | V21: =V52*V13 -> 1768.732 | W21: =W52*W13 -> 1596.971 | X21: =X52*X13 -> 2029.9663 | Y21: =Y52*Y13 -> 2074.6516 | Z21: =Z52*Z13 -> 1853.9446 | AB21: =SUM(C21:F21) -> 3946 | AC21: =SUM(G21:J21) -> 4800 | AD21: =SUM(K21:N21) -> 5150 | AE21: =SUM(O21:R21) -> 5834 | AF21: =SUM(S21:V21) -> 7576.9303 | AG21: =SUM(W21:Z21) -> 7555.5335 | AH21: =SUM(X21:AA21) -> 5958.5625 | AI21: =SUM(Y21:AB21) -> 7874.5962 | AJ21: =SUM(Z21:AC21) -> 10599.945 | AK21: =SUM(AA21:AD21) -> 13896
B22: Restructuring | D22: 142 | F22: 34 | J22: 0 | L22: 622 | M22: 55 | N22: 7 | O22: 94 | Q22: 238 | R22: 162 | T22: 0 | U22: 0 | V22: 0 | W22: 0 | X22: 0 | Y22: 0 | Z22: 0 | AB22: =SUM(C22:F22) -> 176 | AC22: =SUM(G22:J22) -> 0 | AD22: =SUM(K22:N22) -> 684 | AE22: =SUM(O22:R22) -> 494 | AF22: =SUM(S22:V22) -> 0 | AG22: =SUM(W22:Z22) -> 0 | AH22: =SUM(X22:AA22) -> 0 | AI22: =SUM(Y22:AB22) -> 176 | AJ22: =SUM(Z22:AC22) -> 176 | AK22: =SUM(AA22:AD22) -> 860
B23: Total Operating expenses | C23: =C20+C21+C22 -> 1857 | D23: =D20+D21+D22 -> 1770 | E23: =E20+E21+E22 -> 1694 | F23: =F20+F21+F22 -> 1876 | G23: =G20+G21+G22 -> 1847 | H23: =H20+H21+H22 -> 2134 | I23: =I20+I21+I22 -> 2414 | J23: =J20+J21+J22 -> 2374 | ... T23: =T20+T21+T22 -> 4353 | U23: =SUM(U20:U22) -> 4178.2405 | V23: =SUM(V20:V22) -> 3707.7031 | W23: =SUM(W20:W22) -> 3347.6493 | X23: =SUM(X20:X22) -> 4255.3154 | Y23: =SUM(Y20:Y22) -> 4348.9868 | Z23: =SUM(Z20:Z22) -> 3886.33 | AB23: =SUM(C23:F23) -> 7197 | AC23: =SUM(G23:J23) -> 8769 | AD23: =SUM(K23:N23) -> 10374 | AE23: =SUM(O23:R23) -> 12739 | AF23: =SUM(S23:V23) -> 16017.944 | AG23: =SUM(W23:Z23) -> 15838.282 | AH23: =SUM(X23:AA23) -> 12490.632 | AI23: =SUM(Y23:AB23) -> 15432.317 | AJ23: =SUM(Z23:AC23) -> 19852.33 | AK23: =SUM(AA23:AD23) -> 26340
B24: Operating Income | C24: =C19-C23 -> 3603 | D24: =D19-D23 -> 2464 | E24: =E19-E23 -> 3688 | F24: =F19-F23 -> 3901 | G24: =G19-G23 -> 2664 | H24: =H19-H23 -> 2399 | I24: =I19-I23 -> 1764 | J24: =J19-J23 -> 2064 | ... Z24: =Z19-Z23 -> 1548.4193 | AB24: =SUM(C24:F24) -> 13656 | AC24: =SUM(G24:J24) -> 8891 | AD24: =SUM(K24:N24) -> 7076 | AE24: =SUM(O24:R24) -> 4355 | AF24: =SUM(S24:V24) -> 4331.6538 | AG24: =SUM(W24:Z24) -> 5674.2187 | AH24: =SUM(X24:AA24) -> 4526.7083 | AI24: =SUM(Y24:AB24) -> 16779.028 | AJ24: =SUM(Z24:AC24) -> 24095.419 | AK24: =SUM(AA24:AD24) -> 29623
B25: Interest Income | C25: 28 | D25: 26 | E25: 86 | F25: 157 | G25: 213 | H25: 238 | I25: 282 | J25: 333 | K25: 350 | L25: 348 | M25: 429 | N25: 442 | O25: 400 | P25: 392 | Q25: 439 | R25: 449 | S25: 434 | T25: 422 | U25: =AVERAGE(Q25:T25) -> 436 | V25: =U25 -> 436 | W25: =V25 -> 436 | X25: =W25 -> 436 | Y25: =X25 -> 436 | Z25: =Y25 -> 436 | AB25: =SUM(C25:F25) -> 297 | AC25: =SUM(G25:J25) -> 1066 | AD25: =SUM(K25:N25) -> 1569 | AE25: =SUM(O25:R25) -> 1680 | AF25: =SUM(S25:V25) -> 1728 | AG25: =SUM(W25:Z25) -> 1744 | AH25: =SUM(X25:AA25) -> 1308 | AI25: =SUM(Y25:AB25) -> 1169 | AJ25: =SUM(Z25:AC25) -> 1799 | AK25: =SUM(AA25:AD25) -> 2932
B26: Interest Expenses | C26: -61 | D26: -44 | E26: -53 | F26: -33 | G26: -29 | H26: -28 | I26: -38 | J26: -61 | K26: -76 | L26: -86 | M26: -92 | N26: -96 | O26: -91 | P26: -86 | Q26: -76 | R26: -85 | S26: -92 | T26: -81 | U26: =AVERAGE(Q26:T26) -> -83.5 | V26: =U26 -> -83.5 | W26: =V26 -> -83.5 | X26: =W26 -> -83.5 | Y26: =X26 -> -83.5 | Z26: =Y26 -> -83.5 | AB26: =SUM(C26:F26) -> -191 | AC26: =SUM(G26:J26) -> -156 | AD26: =SUM(K26:N26) -> -350 | AE26: =SUM(O26:R26) -> -338 | AF26: =SUM(S26:V26) -> -340 | AG26: =SUM(W26:Z26) -> -334 | AH26: =SUM(X26:AA26) -> -250.5 | AI26: =SUM(Y26:AB26) -> -358 | AJ26: =SUM(Z26:AC26) -> -430.5 | AK26: =SUM(AA26:AD26) -> -697
B27: Other income net | C27: 56 | D27: 28 | E27: -85 | F27: -42 | G27: -48 | H27: 328 | I27: 37 | J27: -145 | K27: 108 | L27: 20 | M27: -263 | N27: 830 | O27: -119 | P27: 320 | Q27: -28 | R27: -592 | S27: -535 | T27: 590 | U27: 0 | V27: 0 | W27: 0 | X27: 0 | Y27: 0 | Z27: 0 | AB27: =SUM(C27:F27) -> -43 | AC27: =SUM(G27:J27) -> 172 | AD27: =SUM(K27:N27) -> 695 | AE27: =SUM(O27:R27) -> -419 | AF27: =SUM(S27:V27) -> 55 | AG27: =SUM(W27:Z27) -> 0 | AH27: =SUM(X27:AA27) -> 0 | AI27: =SUM(Y27:AB27) -> -43 | AJ27: =SUM(Z27:AC27) -> 129 | AK27: =SUM(AA27:AD27) -> 824
B28: Pretax income | C28: =C24+C25+C26+C27 -> 3626 | D28: =D24+D25+D26+D27 -> 2474 | E28: =E24+E25+E26+E27 -> 3636 | F28: =F24+F25+F26+F27 -> 3983 | G28: =G24+G25+G26+G27 -> 2800 | H28: =H24+H25+H26+H27 -> 2937 | I28: =I24+I25+I26+I27 -> 2045 | J28: =J24+J25+J26+J27 -> 2191 | ... T28: =T24+T25+T26+T27 -> 1329 | U28: =SUM(U24:U27) -> 1932.9309 | V28: =SUM(V24:V27) -> 1764.7229 | W28: =SUM(W24:W27) -> 1500.0104 | X28: =SUM(X24:X27) -> 1756.1805 | Y28: =SUM(Y24:Y27) -> 1927.1085 | Z28: =SUM(Z24:Z27) -> 1900.9193 | AB28: =SUM(C28:F28) -> 13719 | AC28: =SUM(G28:J28) -> 9973 | AD28: =SUM(K28:N28) -> 8990 | AE28: =SUM(O28:R28) -> 5278 | AF28: =SUM(S28:V28) -> 5774.6538 | AG28: =SUM(W28:Z28) -> 7084.2187 | AH28: =SUM(X28:AA28) -> 5584.2083 | AI28: =SUM(Y28:AB28) -> 17547.028 | AJ28: =SUM(Z28:AC28) -> 25592.919 | AK28: =SUM(AA28:AD28) -> 32682
B29: Taxes | C29: 346 | D29: 205 | E29: 305 | F29: 276 | G29: 261 | H29: 323 | I29: 167 | J29: -5752 | K29: 409 | L29: 393 | M29: 602 | N29: 433 | O29: 169 | P29: 359 | Q29: 570 | R29: 325 | S29: 257 | T29: 201 | U29: =U28*U54 -> 512.70013 | V29: =V28*V54 -> 468.0838 | W29: =W28*W54 -> 397.87015 | X29: =X28*X54 -> 465.81796 | Y29: =Y28*Y54 -> 511.15577 | Z29: =Z28*Z54 -> 504.2092 | AB29: =SUM(C29:F29) -> 1132 | AC29: =SUM(G29:J29) -> -5001 | AD29: =SUM(K29:N29) -> 1837 | AE29: =SUM(O29:R29) -> 1423 | AF29: =SUM(S29:V29) -> 1438.7839 | AG29: =SUM(W29:Z29) -> 1879.0531 | AH29: =SUM(X29:AA29) -> 1481.1829 | AI29: =SUM(Y29:AB29) -> 2147.365 | AJ29: =SUM(Z29:AC29) -> -3364.7908 | AK29: =SUM(AA29:AD29) -> -2032
B30: Net Income | C30: =C28-C29 -> 3280 | D30: =D28-D29 -> 2269 | E30: =E28-E29 -> 3331 | F30: =F28-F29 -> 3707 | G30: =G28-G29 -> 2539 | H30: =H28-H29 -> 2614 | I30: =I28-I29 -> 1878 | J30: =J28-J29 -> 7943 | ... Z30: =Z28-Z29 -> 1396.7101 | AB30: =SUM(C30:F30) -> 12587 | AC30: =SUM(G30:J30) -> 14974 | AD30: =SUM(K30:N30) -> 7153 | AE30: =SUM(O30:R30) -> 3855 | AF30: =SUM(S30:V30) -> 4335.8699 | AG30: =SUM(W30:Z30) -> 5205.1656 | AH30: =SUM(X30:AA30) -> 4103.0254 | AI30: =SUM(Y30:AB30) -> 15399.663 | AJ30: =SUM(Z30:AC30) -> 28957.71 | AK30: =SUM(AA30:AD30) -> 34714
B31: Less: noncontrolling interests | C31: -38 | D31: 10 | E31: 39 | F31: 20 | G31: 26 | H31: -89 | I31: 25 | J31: 15 | K31: 15 | L31: 16 | M31: 16 | N31: 15 | O31: 11 | P31: 18 | Q31: 16 | R31: 16 | S31: 491 | T31: 14 | U31: 0 | V31: 0 | W31: 0 | X31: 0 | Y31: 0 | Z31: 0 | AB31: =SUM(C31:F31) -> 31 | AC31: =SUM(G31:J31) -> -23 | AD31: =SUM(K31:N31) -> 62 | AE31: =SUM(O31:R31) -> 61 | AF31: =SUM(S31:V31) -> 505 | AG31: =SUM(W31:Z31) -> 0 | AH31: =SUM(X31:AA31) -> 0 | AI31: =SUM(Y31:AB31) -> 31 | AJ31: =SUM(Z31:AC31) -> 8 | AK31: =SUM(AA31:AD31) -> 70
B32: Net income to common stockholders | C32: =C30-C31 -> 3318 | D32: =D30-D31 -> 2259 | E32: =E30-E31 -> 3292 | F32: =F30-F31 -> 3687 | G32: =G30-G31 -> 2513 | H32: =H30-H31 -> 2703 | I32: =I30-I31 -> 1853 | J32: =J30-J31 -> 7928 | ... R32: =R30-R31 -> 840 | S32: 477 | T32: =T30-T31 -> 1114 | U32: =U30-U31 -> 1420.2308 | V32: =V30-V31 -> 1296.6391 | W32: =W30-W31 -> 1102.1402 | X32: =X30-X31 -> 1290.3625 | Y32: =Y30-Y31 -> 1415.9528 | Z32: =Z30-Z31 -> 1396.7101 | AB32: =SUM(C32:F32) -> 12556 | AC32: =SUM(G32:J32) -> 14997 | AD32: =SUM(K32:N32) -> 7091 | AE32: =SUM(O32:R32) -> 3794 | AF32: =SUM(S32:V32) -> 4307.8699 | AG32: =SUM(W32:Z32) -> 5205.1656 | AH32: =SUM(X32:AA32) -> 4103.0254 | AI32: =SUM(Y32:AB32) -> 15368.663 | AJ32: =SUM(Z32:AC32) -> 28949.71 | AK32: =SUM(AA32:AD32) -> 34644
B33: EPS (Earnings Per Shares) | C33: =C32/C34 -> 1.0696325 | D33: =D32/D34 -> 0.72613308 | E33: =E32/E34 -> 1.0464081 | F33: =F32/F34 -> 1.1719644 | G33: =G32/G34 -> 0.79374605 | H33: =H32/H34 -> 0.85375869 | I33: =I32/I34 -> 0.58343829 | J33: =J32/J34 -> 2.4962217 | ... Z33: =Z32/Z34 -> 0.43148288 | AB33: =AB32/AB34 -> 4.0163135 | AC33: =AC32/AC34 -> 4.7294229 | AD33: =AD32/AD34 -> 2.2206216 | AE33: =AE32/AE34 -> 1.1822077 | AF33: =AF32/AF34 -> 1.3308217 | AG33: =AG32/AG34 -> 1.6080215 | AH33: =AH32/AH34 -> 1.2675395 | AI33: =AI32/AI34 -> 4.7478106 | ... AK33: =AK32/AK34 -> 10.702502
B34: Shares | C34: =3*1034 -> 3102 | D34: =1037*3 -> 3111 | E34: 3146 | F34: 3146 | G34: 3166 | H34: 3166 | I34: 3176 | J34: 3176 | K34: 3186 | L34: 3191 | M34: 3198 | N34: 3198 | O34: 3218 | P34: 3223 | Q34: 3198 | R34: 3198 | S34: 3234 | T34: 3237 | U34: 3237 | V34: 3237 | W34: 3237 | X34: 3237 | Y34: 3237 | Z34: 3237 | AB34: =AVERAGE(C34:F34) -> 3126.25 | AC34: =AVERAGE(G34:J34) -> 3171 | AD34: =AVERAGE(K34:N34) -> 3193.25 | AE34: =AVERAGE(O34:R34) -> 3209.25 | AF34: 3237 | AG34: 3237 | AH34: 3237 | AI34: 3237 | AJ34: 3237 | AK34: 3237
B35: Diluted EPS | C35: =C32/C36 -> 0.95592048 | D35: =D32/D36 -> 0.65194805 | E35: =E32/E36 -> 0.94925029 | F35: =F32/F36 -> 1.0631488 | G35: =G32/G36 -> 0.72462514 | H35: =H32/H36 -> 0.77941176 | I35: =I32/I36 -> 0.53048955 | J35: =J32/J36 -> 2.2696822 | ... Z35: =Z32/Z36 -> 0.39455087 | AB35: =AB32/AB36 -> 3.6205306 | AC35: =AC32/AC36 -> 4.3088637 | AD35: =AD32/AD36 -> 2.0319507 | AE35: =AE32/AE36 -> 1.0799118 | AF35: =AF32/AF36 -> 1.2169124 | AG35: =AG32/AG36 -> 1.4703858 | AH35: =AH32/AH36 -> 1.1590467 | AI35: =AI32/AI36 -> 4.3414302 | ... AK35: =AK32/AK36 -> 9.7864407
B36: Diluted Shares | C36: =1157*3 -> 3471 | D36: =3*1155 -> 3465 | E36: 3468 | F36: 3468 | G36: 3468 | H36: 3468 | I36: 3493 | J36: 3493 | K36: 3484 | L36: 3481 | M36: 3497 | N36: 3497 | O36: 3521 | P36: 3538 | Q36: 3497 | R36: 3497 | S36: 5538 | T36: 3540 | U36: 3540 | V36: 3540 | W36: 3540 | X36: 3540 | Y36: 3540 | Z36: 3540 | AB36: =AVERAGE(C36:F36) -> 3468 | AC36: =AVERAGE(G36:J36) -> 3480.5 | AD36: =AVERAGE(K36:N36) -> 3489.75 | AE36: =AVERAGE(O36:R36) -> 3513.25 | AF36: 3540 | AG36: 3540 | AH36: 3540 | AI36: 3540 | AJ36: 3540 | AK36: 3540
A38: Valuation Block
B39: Target P/E Multiple | AF39: 40 | AG39: 40 | AH39: 40 | AI39: 40 | AJ39: 40 | AK39: 40
B40: Current Price Per share | AF40: =Main!$O$3 -> 328.58 | AG40: =Main!$O$3 -> 328.58 | AH40: =Main!$O$3 -> 328.58 | AI40: =Main!$O$3 -> 328.58 | AJ40: =Main!$O$3 -> 328.58 | AK40: =Main!$O$3 -> 328.58
B41: Implied Price Per Share | AF41: =AF35*AF39 -> 48.676496 | AG41: =AG35*AG39 -> 58.81543 | AH41: =AH35*AH39 -> 46.361868 | AI41: =AI35*AI39 -> 173.65721 | AJ41: =AJ35*AJ39 -> 327.11537 | AK41: =AK35*AK39 -> 391.45763
B42: Difference ($) | AF42: =AF41-AF40 -> -279.9035 | AG42: =AG41-AG40 -> -269.76457 | AH42: =AH41-AH40 -> -282.21813 | AI42: =AI41-AI40 -> -154.92279 | AJ42: =AJ41-AJ40 -> -1.4646317 | AK42: =AK41-AK40 -> 62.877627
B43: Upside / (Downside) | AF43: =AF41/AF40-1 -> -0.85185801 | AG43: =AG41/AG40-1 -> -0.82100119 | AH43: =AH41/AH40-1 -> -0.85890234 | AI43: =AI41/AI40-1 -> -0.47149185 | AJ43: =AJ41/AJ40-1 -> -0.0044574586 | AK43: =AK41/AK40-1 -> 0.1913617
B44: ASP (Average selling price) for automotive sales In Dollars | C44: =(C8/C4)*1000000 -> 50037.414 | D44: =(D8/D4)*1000000 -> 53672.039 | E44: =(E8/E4)*1000000 -> 51726.144 | F44: =(F8/F4)*1000000 -> 49943.496 | G44: =(G8/G4)*1000000 -> 44642.034 | H44: =(H8/H4)*1000000 -> 43804.436 | I44: =(I8/I4)*1000000 -> 42711.448 | J44: =(J8/J4)*1000000 -> 42579.364 | ... T44: =(T8/T4)*1000000 -> 41668.229 | U44: =Q44 -> 40955.625 | V44: =R44 -> 40050.021 | W44: =S44 -> 43217.894 | X44: =T44 -> 41668.229 | Y44: =U44 -> 40955.625 | Z44: =V44 -> 40050.021 | AB44: =AB8/SUM(C4:F4)*1000000 -> 51154.964 | AC44: =AC8/SUM(G4:J4)*1000000 -> 43409.17 | AD44: =AD8/SUM(K4:N4)*1000000 -> 40509.136 | AE44: =AE8/SUM(O4:R4)*1000000 -> 40229.713 | AF44: =AF8/SUM(S4:V4)*1000000 -> 41396.655 | AG44: =AG8/SUM(W4:Z4)*1000000 -> 41396.655 | AH44: =AG44 -> 41396.655 | AI44: =AH44 -> 41396.655 | AJ44: =AI44 -> 41396.655 | AK44: =AJ44 -> 41396.655
...
